[ 2023-08-04 22:10:34,390 ] 225 werkzeug - WARNING -  * Running on all addresses.
   WARNING: This is a development server. Do not use it in a production deployment.
[ 2023-08-04 22:10:34,390 ] 225 werkzeug - INFO -  * Running on http://192.168.1.4:9090/ (Press CTRL+C to quit)
[ 2023-08-04 22:10:39,523 ] 225 werkzeug - INFO - 127.0.0.1 - - [04/Aug/2023 22:10:39] "GET /predictdata HTTP/1.1" 200 -
[ 2023-08-04 22:10:39,586 ] 225 werkzeug - INFO - 127.0.0.1 - - [04/Aug/2023 22:10:39] "[33mGET /css/materialize.min.css HTTP/1.1[0m" 404 -
[ 2023-08-04 22:11:50,141 ] 1458 app - ERROR - Exception on /predictdata [POST]
Traceback (most recent call last):
  File "E:\ML_OOP\mlproject_telecom\mlproject_telecom\src\pipeline\predict_pipeline.py", line 22, in predict
    data_scaled = preprocessor.transform(features)
  File "e:\ML_OOP\mlproject_airbnb\mlproject_airbnb\.venv\lib\site-packages\sklearn\compose\_column_transformer.py", line 561, in transform
    "Given feature/column names do not match the ones for the "
RuntimeError: Given feature/column names do not match the ones for the data given during fit.

During handling of the above exception, another exception occurred:

Traceback (most recent call last):
  File "e:\ML_OOP\mlproject_airbnb\mlproject_airbnb\.venv\lib\site-packages\flask\app.py", line 2073, in wsgi_app
    response = self.full_dispatch_request()
  File "e:\ML_OOP\mlproject_airbnb\mlproject_airbnb\.venv\lib\site-packages\flask\app.py", line 1518, in full_dispatch_request
    rv = self.handle_user_exception(e)
  File "e:\ML_OOP\mlproject_airbnb\mlproject_airbnb\.venv\lib\site-packages\flask\app.py", line 1516, in full_dispatch_request
    rv = self.dispatch_request()
  File "e:\ML_OOP\mlproject_airbnb\mlproject_airbnb\.venv\lib\site-packages\flask\app.py", line 1502, in dispatch_request
    return self.ensure_sync(self.view_functions[rule.endpoint])(**req.view_args)
  File "app.py", line 43, in predict_datapoint
    results=predict_pipeline.predict(pred_df)
  File "E:\ML_OOP\mlproject_telecom\mlproject_telecom\src\pipeline\predict_pipeline.py", line 28, in predict
    raise CustomException(e, sys)
src.exception.CustomException: Error occured in python script name [E:\ML_OOP\mlproject_telecom\mlproject_telecom\src\pipeline\predict_pipeline.py] line number [22] error message[Given feature/column names do not match the ones for the data given during fit.]
[ 2023-08-04 22:11:51,897 ] 225 werkzeug - INFO - 127.0.0.1 - - [04/Aug/2023 22:11:51] "[35m[1mPOST /predictdata HTTP/1.1[0m" 500 -
[ 2023-08-04 22:12:40,994 ] 225 werkzeug - INFO - 127.0.0.1 - - [04/Aug/2023 22:12:40] "GET /predictdata HTTP/1.1" 200 -
[ 2023-08-04 22:12:41,058 ] 225 werkzeug - INFO - 127.0.0.1 - - [04/Aug/2023 22:12:41] "[33mGET /css/materialize.min.css HTTP/1.1[0m" 404 -
[ 2023-08-04 22:12:43,970 ] 225 werkzeug - INFO - 127.0.0.1 - - [04/Aug/2023 22:12:43] "GET /predictdata HTTP/1.1" 200 -
[ 2023-08-04 22:12:44,034 ] 225 werkzeug - INFO - 127.0.0.1 - - [04/Aug/2023 22:12:44] "[33mGET /css/materialize.min.css HTTP/1.1[0m" 404 -
[ 2023-08-04 22:12:46,558 ] 225 werkzeug - INFO - 127.0.0.1 - - [04/Aug/2023 22:12:46] "GET /predictdata HTTP/1.1" 200 -
[ 2023-08-04 22:12:46,613 ] 225 werkzeug - INFO - 127.0.0.1 - - [04/Aug/2023 22:12:46] "[33mGET /css/materialize.min.css HTTP/1.1[0m" 404 -
[ 2023-08-04 22:12:59,972 ] 1458 app - ERROR - Exception on /predictdata [POST]
Traceback (most recent call last):
  File "E:\ML_OOP\mlproject_telecom\mlproject_telecom\src\pipeline\predict_pipeline.py", line 22, in predict
    data_scaled = preprocessor.transform(features)
  File "e:\ML_OOP\mlproject_airbnb\mlproject_airbnb\.venv\lib\site-packages\sklearn\compose\_column_transformer.py", line 561, in transform
    "Given feature/column names do not match the ones for the "
RuntimeError: Given feature/column names do not match the ones for the data given during fit.

During handling of the above exception, another exception occurred:

Traceback (most recent call last):
  File "e:\ML_OOP\mlproject_airbnb\mlproject_airbnb\.venv\lib\site-packages\flask\app.py", line 2073, in wsgi_app
    response = self.full_dispatch_request()
  File "e:\ML_OOP\mlproject_airbnb\mlproject_airbnb\.venv\lib\site-packages\flask\app.py", line 1518, in full_dispatch_request
    rv = self.handle_user_exception(e)
  File "e:\ML_OOP\mlproject_airbnb\mlproject_airbnb\.venv\lib\site-packages\flask\app.py", line 1516, in full_dispatch_request
    rv = self.dispatch_request()
  File "e:\ML_OOP\mlproject_airbnb\mlproject_airbnb\.venv\lib\site-packages\flask\app.py", line 1502, in dispatch_request
    return self.ensure_sync(self.view_functions[rule.endpoint])(**req.view_args)
  File "app.py", line 43, in predict_datapoint
    results=predict_pipeline.predict(pred_df)
  File "E:\ML_OOP\mlproject_telecom\mlproject_telecom\src\pipeline\predict_pipeline.py", line 28, in predict
    raise CustomException(e, sys)
src.exception.CustomException: Error occured in python script name [E:\ML_OOP\mlproject_telecom\mlproject_telecom\src\pipeline\predict_pipeline.py] line number [22] error message[Given feature/column names do not match the ones for the data given during fit.]
[ 2023-08-04 22:13:00,006 ] 225 werkzeug - INFO - 127.0.0.1 - - [04/Aug/2023 22:13:00] "[35m[1mPOST /predictdata HTTP/1.1[0m" 500 -
